<?xml version="1.0" encoding="utf-8"?>
<!-- This URDF was automatically created by SolidWorks to URDF Exporter! Originally created by Stephen Brawner (brawner@gmail.com) 
     Commit Version: 1.6.0-1-g15f4949  Build Version: 1.6.7594.29634
     For more information, please see http://wiki.ros.org/sw_urdf_exporter -->
<robot
  name="abot_urdf">
  <link
    name="base_link">
    <inertial>
      <origin
        xyz="3.52930394689292E-18 4.62395285906123E-18 0.0015"
        rpy="0 0 0" />
      <mass
        value="0.468" />
      <inertia
        ixx="0.000390351"
        ixy="4.22838847269347E-20"
        ixz="2.75285707857648E-21"
        iyy="0.001560351"
        iyz="-1.37642853928824E-21"
        izz="0.00195" />
    </inertial>
    <visual>
      <origin
        xyz="0 0 0"
        rpy="0 0 0" />
      <geometry>
        <mesh
          filename="package://abot_urdf/meshes/base_link.STL" />
      </geometry>
      <material
        name="">
        <color
          rgba="0.792156862745098 0.819607843137255 0.933333333333333 1" />
      </material>
    </visual>
    <collision>
      <origin
        xyz="0 0 0"
        rpy="0 0 0" />
      <geometry>
        <mesh
          filename="package://abot_urdf/meshes/base_link.STL" />
      </geometry>
    </collision>
  </link>
  <link
    name="abot_right_wheel">
    <inertial>
      <origin
        xyz="3.46944695195361E-18 0.0125 -6.93889390390723E-18"
        rpy="0 0 0" />
      <mass
        value="0.647069911869073" />
      <inertia
        ixx="0.000204568456512775"
        ixy="1.27775670669039E-21"
        ixz="-6.7762635780344E-21"
        iyy="0.000341733797205854"
        iyz="5.11755138982384E-22"
        izz="0.000204568456512775" />
    </inertial>
    <visual>
      <origin
        xyz="0 0 0"
        rpy="0 0 0" />
      <geometry>
        <mesh
          filename="package://abot_urdf/meshes/abot_right_wheel.STL" />
      </geometry>
      <material
        name="">
        <color
          rgba="0.792156862745098 0.819607843137255 0.933333333333333 1" />
      </material>
    </visual>
    <collision>
      <origin
        xyz="0 0 0"
        rpy="0 0 0" />
      <geometry>
        <mesh
          filename="package://abot_urdf/meshes/abot_right_wheel.STL" />
      </geometry>
    </collision>
  </link>
  <joint
    name="right_wheel_to_base"
    type="continuous">
    <origin
      xyz="0.04 -0.075 0.00300000000000001"
      rpy="0 -1.18984983203427 0" />
    <parent
      link="base_link" />
    <child
      link="abot_right_wheel" />
    <axis
      xyz="0 1 0" />
  </joint>
  <link
    name="abot_left_wheel">
    <inertial>
      <origin
        xyz="3.46944695195361E-18 0.0125 0"
        rpy="0 0 0" />
      <mass
        value="0.647069911869073" />
      <inertia
        ixx="0.000204568456512775"
        ixy="-2.23413781352312E-21"
        ixz="6.7762635780344E-21"
        iyy="0.000341733797205854"
        iyz="-1.60836883992906E-21"
        izz="0.000204568456512775" />
    </inertial>
    <visual>
      <origin
        xyz="0 0 0"
        rpy="0 0 0" />
      <geometry>
        <mesh
          filename="package://abot_urdf/meshes/abot_left_wheel.STL" />
      </geometry>
      <material
        name="">
        <color
          rgba="0.792156862745098 0.819607843137255 0.933333333333333 1" />
      </material>
    </visual>
    <collision>
      <origin
        xyz="0 0 0"
        rpy="0 0 0" />
      <geometry>
        <mesh
          filename="package://abot_urdf/meshes/abot_left_wheel.STL" />
      </geometry>
    </collision>
  </link>
  <joint
    name="left_wheel_to_base"
    type="continuous">
    <origin
      xyz="0.04 0.05 0.00299999999999998"
      rpy="0 -0.946835294948567 0" />
    <parent
      link="base_link" />
    <child
      link="abot_left_wheel" />
    <axis
      xyz="0 1 0" />
  </joint>
  <link
    name="abot_lidar">
    <inertial>
      <origin
        xyz="-0.00405572587504531 -1.00899709035313E-18 0.0256114517500906"
        rpy="0 0 0" />
      <mass
        value="2.61917781597221" />
      <inertia
        ixx="0.00168198342889722"
        ixy="1.2058020378595E-20"
        ixz="0.000232514764416348"
        iyy="0.00261041581110539"
        iyz="-2.56645228638893E-20"
        izz="0.00289840915984011" />
    </inertial>
    <visual>
      <origin
        xyz="0 0 0"
        rpy="0 0 0" />
      <geometry>
        <mesh
          filename="package://abot_urdf/meshes/abot_lidar.STL" />
      </geometry>
      <material
        name="">
        <color
          rgba="0.792156862745098 0.819607843137255 0.933333333333333 1" />
      </material>
    </visual>
    <collision>
      <origin
        xyz="0 0 0"
        rpy="0 0 0" />
      <geometry>
        <mesh
          filename="package://abot_urdf/meshes/abot_lidar.STL" />
      </geometry>
    </collision>
  </link>
  <joint
    name="lidar_to_base"
    type="continuous">
    <origin
      xyz="0 0 0.003"
      rpy="0 0 0" />
    <parent
      link="base_link" />
    <child
      link="abot_lidar" />
    <axis
      xyz="0 0 1" />
  </joint>
</robot>