<?xml version="1.0" encoding="utf-8"?>
<!-- This URDF was automatically created by SolidWorks to URDF Exporter! Originally created by Stephen Brawner (brawner@gmail.com) 
     Commit Version: 1.6.0-1-g15f4949  Build Version: 1.6.7594.29634
     For more information, please see http://wiki.ros.org/sw_urdf_exporter -->
<robot
  name="exp_urdf">
  <link
    name="base_link">
    <inertial>
      <origin
        xyz="0 0.00150000000000001 1.38777878078145E-17"
        rpy="0 0 0" />
      <mass
        value="0.468000000000001" />
      <inertia
        ixx="0.000390351"
        ixy="5.37237652524249E-37"
        ixz="1.82117501628044E-35"
        iyy="0.00195"
        iyz="0"
        izz="0.001560351" />
    </inertial>
    <visual>
      <origin
        xyz="0 0 0"
        rpy="0 0 0" />
      <geometry>
        <mesh
          filename="package://exp_urdf/meshes/base_link.STL" />
      </geometry>
      <material
        name="">
        <color
          rgba="0.792156862745098 0.819607843137255 0.933333333333333 1" />
      </material>
    </visual>
    <collision>
      <origin
        xyz="0 0 0"
        rpy="0 0 0" />
      <geometry>
        <mesh
          filename="package://exp_urdf/meshes/base_link.STL" />
      </geometry>
    </collision>
  </link>
  <link
    name="abot_right_wheel">
    <inertial>
      <origin
        xyz="1.73472347597681E-18 6.93889390390723E-18 0.0125"
        rpy="0 0 0" />
      <mass
        value="0.647069911869073" />
      <inertia
        ixx="0.000204568456512775"
        ixy="8.74462853802417E-37"
        ixz="-6.40186763099391E-37"
        iyy="0.000204568456512775"
        iyz="2.29221398410346E-36"
        izz="0.000341733797205854" />
    </inertial>
    <visual>
      <origin
        xyz="0 0 0"
        rpy="0 0 0" />
      <geometry>
        <mesh
          filename="package://exp_urdf/meshes/abot_right_wheel.STL" />
      </geometry>
      <material
        name="">
        <color
          rgba="0.792156862745098 0.819607843137255 0.933333333333333 1" />
      </material>
    </visual>
    <collision>
      <origin
        xyz="0 0 0"
        rpy="0 0 0" />
      <geometry>
        <mesh
          filename="package://exp_urdf/meshes/abot_right_wheel.STL" />
      </geometry>
    </collision>
  </link>
  <joint
    name="right_wheel_to_base"
    type="continuous">
    <origin
      xyz="-0.04 0.003 -0.075"
      rpy="0 0 0" />
    <parent
      link="base_link" />
    <child
      link="abot_right_wheel" />
    <axis
      xyz="0 0 1" />
  </joint>
  <link
    name="abot_left_wheel">
    <inertial>
      <origin
        xyz="1.73472347597681E-18 6.93889390390723E-18 0.0125"
        rpy="0 0 0" />
      <mass
        value="0.647069911869073" />
      <inertia
        ixx="0.000204568456512775"
        ixy="8.74462853802416E-37"
        ixz="4.83859844563354E-36"
        iyy="0.000204568456512774"
        iyz="0"
        izz="0.000341733797205854" />
    </inertial>
    <visual>
      <origin
        xyz="0 0 0"
        rpy="0 0 0" />
      <geometry>
        <mesh
          filename="package://exp_urdf/meshes/abot_left_wheel.STL" />
      </geometry>
      <material
        name="">
        <color
          rgba="0.792156862745098 0.819607843137255 0.933333333333333 1" />
      </material>
    </visual>
    <collision>
      <origin
        xyz="0 0 0"
        rpy="0 0 0" />
      <geometry>
        <mesh
          filename="package://exp_urdf/meshes/abot_left_wheel.STL" />
      </geometry>
    </collision>
  </link>
  <joint
    name="left_wheel_to_base"
    type="continuous">
    <origin
      xyz="-0.04 0.003 0.05"
      rpy="0 0 0" />
    <parent
      link="base_link" />
    <child
      link="abot_left_wheel" />
    <axis
      xyz="0 0 1" />
  </joint>
</robot>